[2024-06-20T15:17:32.989+0000] {local_task_job_runner.py:120} INFO - ::group::Pre task execution logs
[2024-06-20T15:17:33.039+0000] {taskinstance.py:2076} INFO - Dependencies all met for dep_context=non-requeueable deps ti=<TaskInstance: testing_dag.copy_to_db manual__2024-06-20T15:17:26.152535+00:00 [queued]>
[2024-06-20T15:17:33.052+0000] {taskinstance.py:2076} INFO - Dependencies all met for dep_context=requeueable deps ti=<TaskInstance: testing_dag.copy_to_db manual__2024-06-20T15:17:26.152535+00:00 [queued]>
[2024-06-20T15:17:33.053+0000] {taskinstance.py:2306} INFO - Starting attempt 1 of 2
[2024-06-20T15:17:33.078+0000] {taskinstance.py:2330} INFO - Executing <Task(BashOperator): copy_to_db> on 2024-06-20 15:17:26.152535+00:00
[2024-06-20T15:17:33.095+0000] {warnings.py:112} WARNING - /home/***/.local/lib/python3.12/site-packages/***/task/task_runner/standard_task_runner.py:61: DeprecationWarning: This process (pid=554) is multi-threaded, use of fork() may lead to deadlocks in the child.
  pid = os.fork()

[2024-06-20T15:17:33.097+0000] {standard_task_runner.py:63} INFO - Started process 557 to run task
[2024-06-20T15:17:33.098+0000] {standard_task_runner.py:90} INFO - Running: ['***', 'tasks', 'run', 'testing_dag', 'copy_to_db', 'manual__2024-06-20T15:17:26.152535+00:00', '--job-id', '159', '--raw', '--subdir', 'DAGS_FOLDER/main_dag.py', '--cfg-path', '/tmp/tmphgbpx2p5']
[2024-06-20T15:17:33.102+0000] {standard_task_runner.py:91} INFO - Job 159: Subtask copy_to_db
[2024-06-20T15:17:33.176+0000] {task_command.py:426} INFO - Running <TaskInstance: testing_dag.copy_to_db manual__2024-06-20T15:17:26.152535+00:00 [running]> on host 39e4faefdcb7
[2024-06-20T15:17:33.348+0000] {taskinstance.py:2648} INFO - Exporting env vars: AIRFLOW_CTX_DAG_EMAIL='***@example.com' AIRFLOW_CTX_DAG_OWNER='***' AIRFLOW_CTX_DAG_ID='testing_dag' AIRFLOW_CTX_TASK_ID='copy_to_db' AIRFLOW_CTX_EXECUTION_DATE='2024-06-20T15:17:26.152535+00:00' AIRFLOW_CTX_TRY_NUMBER='1' AIRFLOW_CTX_DAG_RUN_ID='manual__2024-06-20T15:17:26.152535+00:00'
[2024-06-20T15:17:33.350+0000] {taskinstance.py:430} INFO - ::endgroup::
[2024-06-20T15:17:33.361+0000] {subprocess.py:63} INFO - Tmp dir root location: /tmp
[2024-06-20T15:17:33.364+0000] {subprocess.py:75} INFO - Running command: ['/usr/bin/bash', '-c', 'docker cp /opt/***/data/output/landing_file_test.csv postgres-db-volume:/var/lib/postgresql/data']
[2024-06-20T15:17:33.397+0000] {subprocess.py:86} INFO - Output:
[2024-06-20T15:17:34.414+0000] {subprocess.py:93} INFO - Error response from daemon: No such container: postgres-db-volume
[2024-06-20T15:17:34.417+0000] {subprocess.py:97} INFO - Command exited with return code 1
[2024-06-20T15:17:34.423+0000] {taskinstance.py:441} INFO - ::group::Post task execution logs
[2024-06-20T15:17:34.442+0000] {taskinstance.py:2905} ERROR - Task failed with exception
Traceback (most recent call last):
  File "/home/airflow/.local/lib/python3.12/site-packages/airflow/models/taskinstance.py", line 465, in _execute_task
    result = _execute_callable(context=context, **execute_callable_kwargs)
             ^^^^^^^^^^^^^^^^^^^^^^^^^^^^^^^^^^^^^^^^^^^^^^^^^^^^^^^^^^^^^
  File "/home/airflow/.local/lib/python3.12/site-packages/airflow/models/taskinstance.py", line 432, in _execute_callable
    return execute_callable(context=context, **execute_callable_kwargs)
           ^^^^^^^^^^^^^^^^^^^^^^^^^^^^^^^^^^^^^^^^^^^^^^^^^^^^^^^^^^^^
  File "/home/airflow/.local/lib/python3.12/site-packages/airflow/models/baseoperator.py", line 401, in wrapper
    return func(self, *args, **kwargs)
           ^^^^^^^^^^^^^^^^^^^^^^^^^^^
  File "/home/airflow/.local/lib/python3.12/site-packages/airflow/operators/bash.py", line 243, in execute
    raise AirflowException(
airflow.exceptions.AirflowException: Bash command failed. The command returned a non-zero exit code 1.
[2024-06-20T15:17:34.491+0000] {taskinstance.py:1206} INFO - Marking task as UP_FOR_RETRY. dag_id=testing_dag, task_id=copy_to_db, run_id=manual__2024-06-20T15:17:26.152535+00:00, execution_date=20240620T151726, start_date=20240620T151733, end_date=20240620T151734
[2024-06-20T15:17:34.542+0000] {standard_task_runner.py:110} ERROR - Failed to execute job 159 for task copy_to_db (Bash command failed. The command returned a non-zero exit code 1.; 557)
[2024-06-20T15:17:34.598+0000] {local_task_job_runner.py:240} INFO - Task exited with return code 1
[2024-06-20T15:17:34.621+0000] {taskinstance.py:3503} INFO - 0 downstream tasks scheduled from follow-on schedule check
[2024-06-20T15:17:34.623+0000] {local_task_job_runner.py:222} INFO - ::endgroup::
