[2024-06-20T12:26:12.089+0000] {local_task_job_runner.py:120} INFO - ::group::Pre task execution logs
[2024-06-20T12:26:12.111+0000] {taskinstance.py:2076} INFO - Dependencies all met for dep_context=non-requeueable deps ti=<TaskInstance: testing_dag.load_data manual__2024-06-20T12:25:54.137899+00:00 [queued]>
[2024-06-20T12:26:12.117+0000] {taskinstance.py:2076} INFO - Dependencies all met for dep_context=requeueable deps ti=<TaskInstance: testing_dag.load_data manual__2024-06-20T12:25:54.137899+00:00 [queued]>
[2024-06-20T12:26:12.118+0000] {taskinstance.py:2306} INFO - Starting attempt 1 of 2
[2024-06-20T12:26:12.130+0000] {taskinstance.py:2330} INFO - Executing <Task(SQLExecuteQueryOperator): load_data> on 2024-06-20 12:25:54.137899+00:00
[2024-06-20T12:26:12.138+0000] {warnings.py:112} WARNING - /home/***/.local/lib/python3.12/site-packages/***/task/task_runner/standard_task_runner.py:61: DeprecationWarning: This process (pid=277) is multi-threaded, use of fork() may lead to deadlocks in the child.
  pid = os.fork()

[2024-06-20T12:26:12.140+0000] {standard_task_runner.py:63} INFO - Started process 279 to run task
[2024-06-20T12:26:12.140+0000] {standard_task_runner.py:90} INFO - Running: ['***', 'tasks', 'run', 'testing_dag', 'load_data', 'manual__2024-06-20T12:25:54.137899+00:00', '--job-id', '111', '--raw', '--subdir', 'DAGS_FOLDER/main_dag.py', '--cfg-path', '/tmp/tmpwydaexbr']
[2024-06-20T12:26:12.141+0000] {standard_task_runner.py:91} INFO - Job 111: Subtask load_data
[2024-06-20T12:26:12.187+0000] {task_command.py:426} INFO - Running <TaskInstance: testing_dag.load_data manual__2024-06-20T12:25:54.137899+00:00 [running]> on host 3c14a6b849f8
[2024-06-20T12:26:12.273+0000] {taskinstance.py:2648} INFO - Exporting env vars: AIRFLOW_CTX_DAG_EMAIL='***@example.com' AIRFLOW_CTX_DAG_OWNER='***' AIRFLOW_CTX_DAG_ID='testing_dag' AIRFLOW_CTX_TASK_ID='load_data' AIRFLOW_CTX_EXECUTION_DATE='2024-06-20T12:25:54.137899+00:00' AIRFLOW_CTX_TRY_NUMBER='1' AIRFLOW_CTX_DAG_RUN_ID='manual__2024-06-20T12:25:54.137899+00:00'
[2024-06-20T12:26:12.275+0000] {taskinstance.py:430} INFO - ::endgroup::
[2024-06-20T12:26:12.276+0000] {sql.py:276} INFO - Executing: BEGIN TRANSACTION;
COPY raw_external_fund FROM 'landing_file.csv' WITH (FORMAT CSV);
COMMIT;
[2024-06-20T12:26:12.283+0000] {base.py:84} INFO - Using connection ID 'postgres_***' for task execution.
[2024-06-20T12:26:12.292+0000] {base.py:84} INFO - Using connection ID 'postgres_***' for task execution.
[2024-06-20T12:26:12.332+0000] {sql.py:487} INFO - Running statement: BEGIN TRANSACTION;
COPY raw_external_fund FROM 'landing_file.csv' WITH (FORMAT CSV);
COMMIT;, parameters: None
[2024-06-20T12:26:12.341+0000] {taskinstance.py:441} INFO - ::group::Post task execution logs
[2024-06-20T12:26:12.342+0000] {taskinstance.py:2905} ERROR - Task failed with exception
Traceback (most recent call last):
  File "/home/airflow/.local/lib/python3.12/site-packages/airflow/models/taskinstance.py", line 465, in _execute_task
    result = _execute_callable(context=context, **execute_callable_kwargs)
             ^^^^^^^^^^^^^^^^^^^^^^^^^^^^^^^^^^^^^^^^^^^^^^^^^^^^^^^^^^^^^
  File "/home/airflow/.local/lib/python3.12/site-packages/airflow/models/taskinstance.py", line 432, in _execute_callable
    return execute_callable(context=context, **execute_callable_kwargs)
           ^^^^^^^^^^^^^^^^^^^^^^^^^^^^^^^^^^^^^^^^^^^^^^^^^^^^^^^^^^^^
  File "/home/airflow/.local/lib/python3.12/site-packages/airflow/models/baseoperator.py", line 401, in wrapper
    return func(self, *args, **kwargs)
           ^^^^^^^^^^^^^^^^^^^^^^^^^^^
  File "/home/airflow/.local/lib/python3.12/site-packages/airflow/providers/common/sql/operators/sql.py", line 282, in execute
    output = hook.run(
             ^^^^^^^^^
  File "/home/airflow/.local/lib/python3.12/site-packages/airflow/providers/common/sql/hooks/sql.py", line 435, in run
    self._run_command(cur, sql_statement, parameters)
  File "/home/airflow/.local/lib/python3.12/site-packages/airflow/providers/common/sql/hooks/sql.py", line 492, in _run_command
    cur.execute(sql_statement)
psycopg2.errors.UndefinedFile: could not open file "landing_file.csv" for reading: No such file or directory
HINT:  COPY FROM instructs the PostgreSQL server process to read a file. You may want a client-side facility such as psql's \copy.

[2024-06-20T12:26:12.356+0000] {taskinstance.py:1206} INFO - Marking task as UP_FOR_RETRY. dag_id=testing_dag, task_id=load_data, run_id=manual__2024-06-20T12:25:54.137899+00:00, execution_date=20240620T122554, start_date=20240620T122612, end_date=20240620T122612
[2024-06-20T12:26:12.367+0000] {standard_task_runner.py:110} ERROR - Failed to execute job 111 for task load_data (could not open file "landing_file.csv" for reading: No such file or directory
HINT:  COPY FROM instructs the PostgreSQL server process to read a file. You may want a client-side facility such as psql's \copy.
; 279)
[2024-06-20T12:26:12.395+0000] {local_task_job_runner.py:240} INFO - Task exited with return code 1
[2024-06-20T12:26:12.409+0000] {taskinstance.py:3503} INFO - 0 downstream tasks scheduled from follow-on schedule check
[2024-06-20T12:26:12.411+0000] {local_task_job_runner.py:222} INFO - ::endgroup::
