[2024-06-21T01:08:49.076+0000] {scheduler_job_runner.py:769} ERROR - Executor reports task instance <TaskInstance: testing_dag.initialise_external_data_table manual__2024-06-21T01:08:17.550975+00:00 [queued]> finished (failed) although the task says it's queued. (Info: None) Was the task killed externally?
