[2024-06-19T13:54:08.604+0000] {local_task_job_runner.py:120} INFO - ::group::Pre task execution logs
[2024-06-19T13:54:08.630+0000] {taskinstance.py:2076} INFO - Dependencies all met for dep_context=non-requeueable deps ti=<TaskInstance: testing_dag.task_2 manual__2024-06-19T13:54:00.440622+00:00 [queued]>
[2024-06-19T13:54:08.638+0000] {taskinstance.py:2076} INFO - Dependencies all met for dep_context=requeueable deps ti=<TaskInstance: testing_dag.task_2 manual__2024-06-19T13:54:00.440622+00:00 [queued]>
[2024-06-19T13:54:08.640+0000] {taskinstance.py:2306} INFO - Starting attempt 1 of 2
[2024-06-19T13:54:08.654+0000] {taskinstance.py:2330} INFO - Executing <Task(PythonOperator): task_2> on 2024-06-19 13:54:00.440622+00:00
[2024-06-19T13:54:08.664+0000] {warnings.py:112} WARNING - /home/***/.local/lib/python3.12/site-packages/***/task/task_runner/standard_task_runner.py:61: DeprecationWarning: This process (pid=91) is multi-threaded, use of fork() may lead to deadlocks in the child.
  pid = os.fork()

[2024-06-19T13:54:08.668+0000] {standard_task_runner.py:63} INFO - Started process 95 to run task
[2024-06-19T13:54:08.668+0000] {standard_task_runner.py:90} INFO - Running: ['***', 'tasks', 'run', 'testing_dag', 'task_2', 'manual__2024-06-19T13:54:00.440622+00:00', '--job-id', '22', '--raw', '--subdir', 'DAGS_FOLDER/main_dag.py', '--cfg-path', '/tmp/tmp57gabeig']
[2024-06-19T13:54:08.669+0000] {standard_task_runner.py:91} INFO - Job 22: Subtask task_2
[2024-06-19T13:54:08.788+0000] {task_command.py:426} INFO - Running <TaskInstance: testing_dag.task_2 manual__2024-06-19T13:54:00.440622+00:00 [running]> on host 4688097978b5
[2024-06-19T13:54:09.012+0000] {taskinstance.py:2648} INFO - Exporting env vars: AIRFLOW_CTX_DAG_EMAIL='***@example.com' AIRFLOW_CTX_DAG_OWNER='***' AIRFLOW_CTX_DAG_ID='testing_dag' AIRFLOW_CTX_TASK_ID='task_2' AIRFLOW_CTX_EXECUTION_DATE='2024-06-19T13:54:00.440622+00:00' AIRFLOW_CTX_TRY_NUMBER='1' AIRFLOW_CTX_DAG_RUN_ID='manual__2024-06-19T13:54:00.440622+00:00'
[2024-06-19T13:54:09.016+0000] {taskinstance.py:430} INFO - ::endgroup::
[2024-06-19T13:54:09.025+0000] {taskinstance.py:441} INFO - ::group::Post task execution logs
[2024-06-19T13:54:09.026+0000] {taskinstance.py:2905} ERROR - Task failed with exception
Traceback (most recent call last):
  File "/home/airflow/.local/lib/python3.12/site-packages/airflow/models/taskinstance.py", line 465, in _execute_task
    result = _execute_callable(context=context, **execute_callable_kwargs)
             ^^^^^^^^^^^^^^^^^^^^^^^^^^^^^^^^^^^^^^^^^^^^^^^^^^^^^^^^^^^^^
  File "/home/airflow/.local/lib/python3.12/site-packages/airflow/models/taskinstance.py", line 432, in _execute_callable
    return execute_callable(context=context, **execute_callable_kwargs)
           ^^^^^^^^^^^^^^^^^^^^^^^^^^^^^^^^^^^^^^^^^^^^^^^^^^^^^^^^^^^^
  File "/home/airflow/.local/lib/python3.12/site-packages/airflow/models/baseoperator.py", line 401, in wrapper
    return func(self, *args, **kwargs)
           ^^^^^^^^^^^^^^^^^^^^^^^^^^^
  File "/home/airflow/.local/lib/python3.12/site-packages/airflow/operators/python.py", line 235, in execute
    return_value = self.execute_callable()
                   ^^^^^^^^^^^^^^^^^^^^^^^
  File "/home/airflow/.local/lib/python3.12/site-packages/airflow/operators/python.py", line 252, in execute_callable
    return self.python_callable(*self.op_args, **self.op_kwargs)
           ^^^^^^^^^^^^^^^^^^^^^^^^^^^^^^^^^^^^^^^^^^^^^^^^^^^^^
  File "/opt/airflow/dags/main_dag.py", line 85, in extract_as_control_table
    file_df = find_csv_filenames()
              ^^^^^^^^^^^^^^^^^^^^
  File "/opt/airflow/dags/main_dag.py", line 57, in find_csv_filenames
    filenames = os.listdir(path_to_dir)
                ^^^^^^^^^^^^^^^^^^^^^^^
FileNotFoundError: [Errno 2] No such file or directory: '/opt/airflow/data/external-funds/external-funds'
[2024-06-19T13:54:09.044+0000] {taskinstance.py:1206} INFO - Marking task as UP_FOR_RETRY. dag_id=testing_dag, task_id=task_2, run_id=manual__2024-06-19T13:54:00.440622+00:00, execution_date=20240619T135400, start_date=20240619T135408, end_date=20240619T135409
[2024-06-19T13:54:09.064+0000] {standard_task_runner.py:110} ERROR - Failed to execute job 22 for task task_2 ([Errno 2] No such file or directory: '/opt/airflow/data/external-funds/external-funds'; 95)
[2024-06-19T13:54:09.086+0000] {local_task_job_runner.py:240} INFO - Task exited with return code 1
[2024-06-19T13:54:09.103+0000] {taskinstance.py:3503} INFO - 0 downstream tasks scheduled from follow-on schedule check
[2024-06-19T13:54:09.105+0000] {local_task_job_runner.py:222} INFO - ::endgroup::
