[2024-06-20T14:14:45.927+0000] {local_task_job_runner.py:120} INFO - ::group::Pre task execution logs
[2024-06-20T14:14:45.958+0000] {taskinstance.py:2076} INFO - Dependencies all met for dep_context=non-requeueable deps ti=<TaskInstance: testing_dag.load_data manual__2024-06-20T14:09:22.694291+00:00 [queued]>
[2024-06-20T14:14:45.967+0000] {taskinstance.py:2076} INFO - Dependencies all met for dep_context=requeueable deps ti=<TaskInstance: testing_dag.load_data manual__2024-06-20T14:09:22.694291+00:00 [queued]>
[2024-06-20T14:14:45.968+0000] {taskinstance.py:2306} INFO - Starting attempt 2 of 2
[2024-06-20T14:14:45.981+0000] {taskinstance.py:2330} INFO - Executing <Task(SQLExecuteQueryOperator): load_data> on 2024-06-20 14:09:22.694291+00:00
[2024-06-20T14:14:45.992+0000] {warnings.py:112} WARNING - /home/***/.local/lib/python3.12/site-packages/***/task/task_runner/standard_task_runner.py:61: DeprecationWarning: This process (pid=1697) is multi-threaded, use of fork() may lead to deadlocks in the child.
  pid = os.fork()

[2024-06-20T14:14:45.993+0000] {standard_task_runner.py:90} INFO - Running: ['***', 'tasks', 'run', 'testing_dag', 'load_data', 'manual__2024-06-20T14:09:22.694291+00:00', '--job-id', '135', '--raw', '--subdir', 'DAGS_FOLDER/main_dag.py', '--cfg-path', '/tmp/tmprkp_lwha']
[2024-06-20T14:14:45.994+0000] {standard_task_runner.py:63} INFO - Started process 1699 to run task
[2024-06-20T14:14:45.994+0000] {standard_task_runner.py:91} INFO - Job 135: Subtask load_data
[2024-06-20T14:14:46.096+0000] {task_command.py:426} INFO - Running <TaskInstance: testing_dag.load_data manual__2024-06-20T14:09:22.694291+00:00 [running]> on host 3c14a6b849f8
[2024-06-20T14:14:46.251+0000] {taskinstance.py:2648} INFO - Exporting env vars: AIRFLOW_CTX_DAG_EMAIL='***@example.com' AIRFLOW_CTX_DAG_OWNER='***' AIRFLOW_CTX_DAG_ID='testing_dag' AIRFLOW_CTX_TASK_ID='load_data' AIRFLOW_CTX_EXECUTION_DATE='2024-06-20T14:09:22.694291+00:00' AIRFLOW_CTX_TRY_NUMBER='2' AIRFLOW_CTX_DAG_RUN_ID='manual__2024-06-20T14:09:22.694291+00:00'
[2024-06-20T14:14:46.254+0000] {taskinstance.py:430} INFO - ::endgroup::
[2024-06-20T14:14:46.256+0000] {sql.py:276} INFO - Executing: copy raw_external_fund 
       FROM '/opt/***/data/output/landing_file.csv' 
       DELIMITER ',' CSV;
       
[2024-06-20T14:14:46.271+0000] {base.py:84} INFO - Using connection ID 'postgres_***' for task execution.
[2024-06-20T14:14:46.298+0000] {base.py:84} INFO - Using connection ID 'postgres_***' for task execution.
[2024-06-20T14:14:46.352+0000] {sql.py:487} INFO - Running statement: copy raw_external_fund 
       FROM '/opt/***/data/output/landing_file.csv' 
       DELIMITER ',' CSV;
       , parameters: None
[2024-06-20T14:14:46.361+0000] {taskinstance.py:441} INFO - ::group::Post task execution logs
[2024-06-20T14:14:46.362+0000] {taskinstance.py:2905} ERROR - Task failed with exception
Traceback (most recent call last):
  File "/home/airflow/.local/lib/python3.12/site-packages/airflow/models/taskinstance.py", line 465, in _execute_task
    result = _execute_callable(context=context, **execute_callable_kwargs)
             ^^^^^^^^^^^^^^^^^^^^^^^^^^^^^^^^^^^^^^^^^^^^^^^^^^^^^^^^^^^^^
  File "/home/airflow/.local/lib/python3.12/site-packages/airflow/models/taskinstance.py", line 432, in _execute_callable
    return execute_callable(context=context, **execute_callable_kwargs)
           ^^^^^^^^^^^^^^^^^^^^^^^^^^^^^^^^^^^^^^^^^^^^^^^^^^^^^^^^^^^^
  File "/home/airflow/.local/lib/python3.12/site-packages/airflow/models/baseoperator.py", line 401, in wrapper
    return func(self, *args, **kwargs)
           ^^^^^^^^^^^^^^^^^^^^^^^^^^^
  File "/home/airflow/.local/lib/python3.12/site-packages/airflow/providers/common/sql/operators/sql.py", line 282, in execute
    output = hook.run(
             ^^^^^^^^^
  File "/home/airflow/.local/lib/python3.12/site-packages/airflow/providers/common/sql/hooks/sql.py", line 435, in run
    self._run_command(cur, sql_statement, parameters)
  File "/home/airflow/.local/lib/python3.12/site-packages/airflow/providers/common/sql/hooks/sql.py", line 492, in _run_command
    cur.execute(sql_statement)
psycopg2.errors.UndefinedFile: could not open file "/opt/***/data/output/landing_file.csv" for reading: No such file or directory
HINT:  COPY FROM instructs the PostgreSQL server process to read a file. You may want a client-side facility such as psql's \copy.

[2024-06-20T14:14:46.376+0000] {taskinstance.py:1206} INFO - Marking task as FAILED. dag_id=testing_dag, task_id=load_data, run_id=manual__2024-06-20T14:09:22.694291+00:00, execution_date=20240620T140922, start_date=20240620T141445, end_date=20240620T141446
[2024-06-20T14:14:46.393+0000] {standard_task_runner.py:110} ERROR - Failed to execute job 135 for task load_data (could not open file "/opt/***/data/output/landing_file.csv" for reading: No such file or directory
HINT:  COPY FROM instructs the PostgreSQL server process to read a file. You may want a client-side facility such as psql's \copy.
; 1699)
[2024-06-20T14:14:46.409+0000] {local_task_job_runner.py:240} INFO - Task exited with return code 1
[2024-06-20T14:14:46.424+0000] {taskinstance.py:3503} INFO - 0 downstream tasks scheduled from follow-on schedule check
[2024-06-20T14:14:46.426+0000] {local_task_job_runner.py:222} INFO - ::endgroup::
