[2024-06-20T12:19:50.425+0000] {scheduler_job_runner.py:1562} WARNING - Marking task instance <TaskInstance: testing_dag.initialise_reference_table_creation manual__2024-06-20T12:07:14.490238+00:00 [queued]> stuck in queued as failed. If the task instance has available retries, it will be retried.
[2024-06-20T12:19:50.615+0000] {scheduler_job_runner.py:769} ERROR - Executor reports task instance <TaskInstance: testing_dag.initialise_reference_table_creation manual__2024-06-20T12:07:14.490238+00:00 [queued]> finished (failed) although the task says it's queued. (Info: None) Was the task killed externally?
