[2024-06-19T14:37:49.229+0000] {local_task_job_runner.py:120} INFO - ::group::Pre task execution logs
[2024-06-19T14:37:49.264+0000] {taskinstance.py:2076} INFO - Dependencies all met for dep_context=non-requeueable deps ti=<TaskInstance: testing_dag.task_3 manual__2024-06-19T14:32:34.573297+00:00 [queued]>
[2024-06-19T14:37:49.272+0000] {taskinstance.py:2076} INFO - Dependencies all met for dep_context=requeueable deps ti=<TaskInstance: testing_dag.task_3 manual__2024-06-19T14:32:34.573297+00:00 [queued]>
[2024-06-19T14:37:49.273+0000] {taskinstance.py:2306} INFO - Starting attempt 2 of 2
[2024-06-19T14:37:49.291+0000] {taskinstance.py:2330} INFO - Executing <Task(PythonOperator): task_3> on 2024-06-19 14:32:34.573297+00:00
[2024-06-19T14:37:49.304+0000] {warnings.py:112} WARNING - /home/***/.local/lib/python3.12/site-packages/***/task/task_runner/standard_task_runner.py:61: DeprecationWarning: This process (pid=590) is multi-threaded, use of fork() may lead to deadlocks in the child.
  pid = os.fork()

[2024-06-19T14:37:49.306+0000] {standard_task_runner.py:63} INFO - Started process 592 to run task
[2024-06-19T14:37:49.306+0000] {standard_task_runner.py:90} INFO - Running: ['***', 'tasks', 'run', 'testing_dag', 'task_3', 'manual__2024-06-19T14:32:34.573297+00:00', '--job-id', '34', '--raw', '--subdir', 'DAGS_FOLDER/main_dag.py', '--cfg-path', '/tmp/tmpq48oc6kp']
[2024-06-19T14:37:49.308+0000] {standard_task_runner.py:91} INFO - Job 34: Subtask task_3
[2024-06-19T14:37:49.391+0000] {task_command.py:426} INFO - Running <TaskInstance: testing_dag.task_3 manual__2024-06-19T14:32:34.573297+00:00 [running]> on host 80ed35ae19d6
[2024-06-19T14:37:49.516+0000] {taskinstance.py:2648} INFO - Exporting env vars: AIRFLOW_CTX_DAG_EMAIL='***@example.com' AIRFLOW_CTX_DAG_OWNER='***' AIRFLOW_CTX_DAG_ID='testing_dag' AIRFLOW_CTX_TASK_ID='task_3' AIRFLOW_CTX_EXECUTION_DATE='2024-06-19T14:32:34.573297+00:00' AIRFLOW_CTX_TRY_NUMBER='2' AIRFLOW_CTX_DAG_RUN_ID='manual__2024-06-19T14:32:34.573297+00:00'
[2024-06-19T14:37:49.517+0000] {taskinstance.py:430} INFO - ::endgroup::
[2024-06-19T14:37:49.533+0000] {logging_mixin.py:188} INFO - Error: The conn_id `cursor` isn't defined
[2024-06-19T14:37:49.539+0000] {taskinstance.py:441} INFO - ::group::Post task execution logs
[2024-06-19T14:37:49.551+0000] {taskinstance.py:2905} ERROR - Task failed with exception
Traceback (most recent call last):
  File "/opt/airflow/dags/main_dag.py", line 46, in init_load_ref_tables
    curs = conn.cursor()
           ^^^^^^^^^^^
  File "/home/airflow/.local/lib/python3.12/site-packages/airflow/utils/context.py", line 133, in __getattr__
    self.var = Connection.get_connection_from_secrets(key)
               ^^^^^^^^^^^^^^^^^^^^^^^^^^^^^^^^^^^^^^^^^^^
  File "/home/airflow/.local/lib/python3.12/site-packages/airflow/models/connection.py", line 519, in get_connection_from_secrets
    raise AirflowNotFoundException(f"The conn_id `{conn_id}` isn't defined")
airflow.exceptions.AirflowNotFoundException: The conn_id `cursor` isn't defined

During handling of the above exception, another exception occurred:

Traceback (most recent call last):
  File "/home/airflow/.local/lib/python3.12/site-packages/airflow/models/taskinstance.py", line 465, in _execute_task
    result = _execute_callable(context=context, **execute_callable_kwargs)
             ^^^^^^^^^^^^^^^^^^^^^^^^^^^^^^^^^^^^^^^^^^^^^^^^^^^^^^^^^^^^^
  File "/home/airflow/.local/lib/python3.12/site-packages/airflow/models/taskinstance.py", line 432, in _execute_callable
    return execute_callable(context=context, **execute_callable_kwargs)
           ^^^^^^^^^^^^^^^^^^^^^^^^^^^^^^^^^^^^^^^^^^^^^^^^^^^^^^^^^^^^
  File "/home/airflow/.local/lib/python3.12/site-packages/airflow/models/baseoperator.py", line 401, in wrapper
    return func(self, *args, **kwargs)
           ^^^^^^^^^^^^^^^^^^^^^^^^^^^
  File "/home/airflow/.local/lib/python3.12/site-packages/airflow/operators/python.py", line 235, in execute
    return_value = self.execute_callable()
                   ^^^^^^^^^^^^^^^^^^^^^^^
  File "/home/airflow/.local/lib/python3.12/site-packages/airflow/operators/python.py", line 252, in execute_callable
    return self.python_callable(*self.op_args, **self.op_kwargs)
           ^^^^^^^^^^^^^^^^^^^^^^^^^^^^^^^^^^^^^^^^^^^^^^^^^^^^^
  File "/opt/airflow/dags/main_dag.py", line 52, in init_load_ref_tables
    conn.rollback()
    ^^^^^^^^^^^^^
  File "/home/airflow/.local/lib/python3.12/site-packages/airflow/utils/context.py", line 133, in __getattr__
    self.var = Connection.get_connection_from_secrets(key)
               ^^^^^^^^^^^^^^^^^^^^^^^^^^^^^^^^^^^^^^^^^^^
  File "/home/airflow/.local/lib/python3.12/site-packages/airflow/models/connection.py", line 519, in get_connection_from_secrets
    raise AirflowNotFoundException(f"The conn_id `{conn_id}` isn't defined")
airflow.exceptions.AirflowNotFoundException: The conn_id `rollback` isn't defined
[2024-06-19T14:37:49.565+0000] {taskinstance.py:1206} INFO - Marking task as FAILED. dag_id=testing_dag, task_id=task_3, run_id=manual__2024-06-19T14:32:34.573297+00:00, execution_date=20240619T143234, start_date=20240619T143749, end_date=20240619T143749
[2024-06-19T14:37:49.584+0000] {standard_task_runner.py:110} ERROR - Failed to execute job 34 for task task_3 (The conn_id `rollback` isn't defined; 592)
[2024-06-19T14:37:49.604+0000] {local_task_job_runner.py:240} INFO - Task exited with return code 1
[2024-06-19T14:37:49.632+0000] {taskinstance.py:3503} INFO - 0 downstream tasks scheduled from follow-on schedule check
[2024-06-19T14:37:49.635+0000] {local_task_job_runner.py:222} INFO - ::endgroup::
