[2024-06-19T13:55:26.470+0000] {local_task_job_runner.py:120} INFO - ::group::Pre task execution logs
[2024-06-19T13:55:26.531+0000] {taskinstance.py:2076} INFO - Dependencies all met for dep_context=non-requeueable deps ti=<TaskInstance: testing_dag.task_2 manual__2024-06-19T13:55:18.384313+00:00 [queued]>
[2024-06-19T13:55:26.545+0000] {taskinstance.py:2076} INFO - Dependencies all met for dep_context=requeueable deps ti=<TaskInstance: testing_dag.task_2 manual__2024-06-19T13:55:18.384313+00:00 [queued]>
[2024-06-19T13:55:26.546+0000] {taskinstance.py:2306} INFO - Starting attempt 1 of 2
[2024-06-19T13:55:26.575+0000] {taskinstance.py:2330} INFO - Executing <Task(PythonOperator): task_2> on 2024-06-19 13:55:18.384313+00:00
[2024-06-19T13:55:26.599+0000] {standard_task_runner.py:90} INFO - Running: ['***', 'tasks', 'run', 'testing_dag', 'task_2', 'manual__2024-06-19T13:55:18.384313+00:00', '--job-id', '25', '--raw', '--subdir', 'DAGS_FOLDER/main_dag.py', '--cfg-path', '/tmp/tmp55pfizh7']
[2024-06-19T13:55:26.599+0000] {warnings.py:112} WARNING - /home/***/.local/lib/python3.12/site-packages/***/task/task_runner/standard_task_runner.py:61: DeprecationWarning: This process (pid=117) is multi-threaded, use of fork() may lead to deadlocks in the child.
  pid = os.fork()

[2024-06-19T13:55:26.605+0000] {standard_task_runner.py:63} INFO - Started process 121 to run task
[2024-06-19T13:55:26.604+0000] {standard_task_runner.py:91} INFO - Job 25: Subtask task_2
[2024-06-19T13:55:26.697+0000] {task_command.py:426} INFO - Running <TaskInstance: testing_dag.task_2 manual__2024-06-19T13:55:18.384313+00:00 [running]> on host 4688097978b5
[2024-06-19T13:55:26.852+0000] {taskinstance.py:2648} INFO - Exporting env vars: AIRFLOW_CTX_DAG_EMAIL='***@example.com' AIRFLOW_CTX_DAG_OWNER='***' AIRFLOW_CTX_DAG_ID='testing_dag' AIRFLOW_CTX_TASK_ID='task_2' AIRFLOW_CTX_EXECUTION_DATE='2024-06-19T13:55:18.384313+00:00' AIRFLOW_CTX_TRY_NUMBER='1' AIRFLOW_CTX_DAG_RUN_ID='manual__2024-06-19T13:55:18.384313+00:00'
[2024-06-19T13:55:26.856+0000] {taskinstance.py:430} INFO - ::endgroup::
[2024-06-19T13:55:26.858+0000] {taskinstance.py:441} INFO - ::group::Post task execution logs
[2024-06-19T13:55:26.859+0000] {taskinstance.py:2905} ERROR - Task failed with exception
Traceback (most recent call last):
  File "/home/airflow/.local/lib/python3.12/site-packages/airflow/models/taskinstance.py", line 465, in _execute_task
    result = _execute_callable(context=context, **execute_callable_kwargs)
             ^^^^^^^^^^^^^^^^^^^^^^^^^^^^^^^^^^^^^^^^^^^^^^^^^^^^^^^^^^^^^
  File "/home/airflow/.local/lib/python3.12/site-packages/airflow/models/taskinstance.py", line 432, in _execute_callable
    return execute_callable(context=context, **execute_callable_kwargs)
           ^^^^^^^^^^^^^^^^^^^^^^^^^^^^^^^^^^^^^^^^^^^^^^^^^^^^^^^^^^^^
  File "/home/airflow/.local/lib/python3.12/site-packages/airflow/models/baseoperator.py", line 401, in wrapper
    return func(self, *args, **kwargs)
           ^^^^^^^^^^^^^^^^^^^^^^^^^^^
  File "/home/airflow/.local/lib/python3.12/site-packages/airflow/operators/python.py", line 235, in execute
    return_value = self.execute_callable()
                   ^^^^^^^^^^^^^^^^^^^^^^^
  File "/home/airflow/.local/lib/python3.12/site-packages/airflow/operators/python.py", line 252, in execute_callable
    return self.python_callable(*self.op_args, **self.op_kwargs)
           ^^^^^^^^^^^^^^^^^^^^^^^^^^^^^^^^^^^^^^^^^^^^^^^^^^^^^
  File "/opt/airflow/dags/main_dag.py", line 85, in extract_as_control_table
    file_df = find_csv_filenames()
              ^^^^^^^^^^^^^^^^^^^^
  File "/opt/airflow/dags/main_dag.py", line 57, in find_csv_filenames
    filenames = os.listdir(path_to_dir)
                ^^^^^^^^^^^^^^^^^^^^^^^
FileNotFoundError: [Errno 2] No such file or directory: '/opt/airflow/data/external-funds/external-funds'
[2024-06-19T13:55:26.885+0000] {taskinstance.py:1206} INFO - Marking task as UP_FOR_RETRY. dag_id=testing_dag, task_id=task_2, run_id=manual__2024-06-19T13:55:18.384313+00:00, execution_date=20240619T135518, start_date=20240619T135526, end_date=20240619T135526
[2024-06-19T13:55:26.910+0000] {standard_task_runner.py:110} ERROR - Failed to execute job 25 for task task_2 ([Errno 2] No such file or directory: '/opt/airflow/data/external-funds/external-funds'; 121)
[2024-06-19T13:55:26.942+0000] {local_task_job_runner.py:240} INFO - Task exited with return code 1
[2024-06-19T13:55:26.962+0000] {taskinstance.py:3503} INFO - 0 downstream tasks scheduled from follow-on schedule check
[2024-06-19T13:55:26.971+0000] {local_task_job_runner.py:222} INFO - ::endgroup::
