[2024-06-20T13:59:41.771+0000] {local_task_job_runner.py:120} INFO - ::group::Pre task execution logs
[2024-06-20T13:59:41.810+0000] {taskinstance.py:2076} INFO - Dependencies all met for dep_context=non-requeueable deps ti=<TaskInstance: testing_dag.copy_to_db manual__2024-06-20T13:54:21.717901+00:00 [queued]>
[2024-06-20T13:59:41.829+0000] {taskinstance.py:2076} INFO - Dependencies all met for dep_context=requeueable deps ti=<TaskInstance: testing_dag.copy_to_db manual__2024-06-20T13:54:21.717901+00:00 [queued]>
[2024-06-20T13:59:41.830+0000] {taskinstance.py:2306} INFO - Starting attempt 2 of 2
[2024-06-20T13:59:41.845+0000] {taskinstance.py:2330} INFO - Executing <Task(BashOperator): copy_to_db> on 2024-06-20 13:54:21.717901+00:00
[2024-06-20T13:59:41.858+0000] {warnings.py:112} WARNING - /home/***/.local/lib/python3.12/site-packages/***/task/task_runner/standard_task_runner.py:61: DeprecationWarning: This process (pid=1486) is multi-threaded, use of fork() may lead to deadlocks in the child.
  pid = os.fork()

[2024-06-20T13:59:41.858+0000] {standard_task_runner.py:90} INFO - Running: ['***', 'tasks', 'run', 'testing_dag', 'copy_to_db', 'manual__2024-06-20T13:54:21.717901+00:00', '--job-id', '130', '--raw', '--subdir', 'DAGS_FOLDER/main_dag.py', '--cfg-path', '/tmp/tmp49gp5oyw']
[2024-06-20T13:59:41.860+0000] {standard_task_runner.py:63} INFO - Started process 1495 to run task
[2024-06-20T13:59:41.860+0000] {standard_task_runner.py:91} INFO - Job 130: Subtask copy_to_db
[2024-06-20T13:59:41.921+0000] {task_command.py:426} INFO - Running <TaskInstance: testing_dag.copy_to_db manual__2024-06-20T13:54:21.717901+00:00 [running]> on host 3c14a6b849f8
[2024-06-20T13:59:42.048+0000] {taskinstance.py:2648} INFO - Exporting env vars: AIRFLOW_CTX_DAG_EMAIL='***@example.com' AIRFLOW_CTX_DAG_OWNER='***' AIRFLOW_CTX_DAG_ID='testing_dag' AIRFLOW_CTX_TASK_ID='copy_to_db' AIRFLOW_CTX_EXECUTION_DATE='2024-06-20T13:54:21.717901+00:00' AIRFLOW_CTX_TRY_NUMBER='2' AIRFLOW_CTX_DAG_RUN_ID='manual__2024-06-20T13:54:21.717901+00:00'
[2024-06-20T13:59:42.050+0000] {taskinstance.py:430} INFO - ::endgroup::
[2024-06-20T13:59:42.063+0000] {subprocess.py:63} INFO - Tmp dir root location: /tmp
[2024-06-20T13:59:42.068+0000] {subprocess.py:75} INFO - Running command: ['/usr/bin/bash', '-c', 'cp -r /opt/***/data/output/landing_file.csv pgdb:/var/lib/postgresql/data/landing_file.csv']
[2024-06-20T13:59:42.088+0000] {subprocess.py:86} INFO - Output:
[2024-06-20T13:59:42.116+0000] {subprocess.py:93} INFO - cp: cannot create regular file 'pgdb:/var/lib/postgresql/data/landing_file.csv': No such file or directory
[2024-06-20T13:59:42.117+0000] {subprocess.py:97} INFO - Command exited with return code 1
[2024-06-20T13:59:42.118+0000] {taskinstance.py:441} INFO - ::group::Post task execution logs
[2024-06-20T13:59:42.127+0000] {taskinstance.py:2905} ERROR - Task failed with exception
Traceback (most recent call last):
  File "/home/airflow/.local/lib/python3.12/site-packages/airflow/models/taskinstance.py", line 465, in _execute_task
    result = _execute_callable(context=context, **execute_callable_kwargs)
             ^^^^^^^^^^^^^^^^^^^^^^^^^^^^^^^^^^^^^^^^^^^^^^^^^^^^^^^^^^^^^
  File "/home/airflow/.local/lib/python3.12/site-packages/airflow/models/taskinstance.py", line 432, in _execute_callable
    return execute_callable(context=context, **execute_callable_kwargs)
           ^^^^^^^^^^^^^^^^^^^^^^^^^^^^^^^^^^^^^^^^^^^^^^^^^^^^^^^^^^^^
  File "/home/airflow/.local/lib/python3.12/site-packages/airflow/models/baseoperator.py", line 401, in wrapper
    return func(self, *args, **kwargs)
           ^^^^^^^^^^^^^^^^^^^^^^^^^^^
  File "/home/airflow/.local/lib/python3.12/site-packages/airflow/operators/bash.py", line 243, in execute
    raise AirflowException(
airflow.exceptions.AirflowException: Bash command failed. The command returned a non-zero exit code 1.
[2024-06-20T13:59:42.132+0000] {taskinstance.py:1206} INFO - Marking task as FAILED. dag_id=testing_dag, task_id=copy_to_db, run_id=manual__2024-06-20T13:54:21.717901+00:00, execution_date=20240620T135421, start_date=20240620T135941, end_date=20240620T135942
[2024-06-20T13:59:42.147+0000] {standard_task_runner.py:110} ERROR - Failed to execute job 130 for task copy_to_db (Bash command failed. The command returned a non-zero exit code 1.; 1495)
[2024-06-20T13:59:42.195+0000] {local_task_job_runner.py:240} INFO - Task exited with return code 1
[2024-06-20T13:59:42.210+0000] {taskinstance.py:3503} INFO - 0 downstream tasks scheduled from follow-on schedule check
[2024-06-20T13:59:42.213+0000] {local_task_job_runner.py:222} INFO - ::endgroup::
