[2024-06-20T13:54:35.128+0000] {local_task_job_runner.py:120} INFO - ::group::Pre task execution logs
[2024-06-20T13:54:35.163+0000] {taskinstance.py:2076} INFO - Dependencies all met for dep_context=non-requeueable deps ti=<TaskInstance: testing_dag.copy_to_db manual__2024-06-20T13:54:21.717901+00:00 [queued]>
[2024-06-20T13:54:35.170+0000] {taskinstance.py:2076} INFO - Dependencies all met for dep_context=requeueable deps ti=<TaskInstance: testing_dag.copy_to_db manual__2024-06-20T13:54:21.717901+00:00 [queued]>
[2024-06-20T13:54:35.171+0000] {taskinstance.py:2306} INFO - Starting attempt 1 of 2
[2024-06-20T13:54:35.185+0000] {taskinstance.py:2330} INFO - Executing <Task(BashOperator): copy_to_db> on 2024-06-20 13:54:21.717901+00:00
[2024-06-20T13:54:35.198+0000] {warnings.py:112} WARNING - /home/***/.local/lib/python3.12/site-packages/***/task/task_runner/standard_task_runner.py:61: DeprecationWarning: This process (pid=1426) is multi-threaded, use of fork() may lead to deadlocks in the child.
  pid = os.fork()

[2024-06-20T13:54:35.200+0000] {standard_task_runner.py:63} INFO - Started process 1428 to run task
[2024-06-20T13:54:35.199+0000] {standard_task_runner.py:90} INFO - Running: ['***', 'tasks', 'run', 'testing_dag', 'copy_to_db', 'manual__2024-06-20T13:54:21.717901+00:00', '--job-id', '129', '--raw', '--subdir', 'DAGS_FOLDER/main_dag.py', '--cfg-path', '/tmp/tmpzeyb7ltp']
[2024-06-20T13:54:35.201+0000] {standard_task_runner.py:91} INFO - Job 129: Subtask copy_to_db
[2024-06-20T13:54:35.286+0000] {task_command.py:426} INFO - Running <TaskInstance: testing_dag.copy_to_db manual__2024-06-20T13:54:21.717901+00:00 [running]> on host 3c14a6b849f8
[2024-06-20T13:54:35.443+0000] {taskinstance.py:2648} INFO - Exporting env vars: AIRFLOW_CTX_DAG_EMAIL='***@example.com' AIRFLOW_CTX_DAG_OWNER='***' AIRFLOW_CTX_DAG_ID='testing_dag' AIRFLOW_CTX_TASK_ID='copy_to_db' AIRFLOW_CTX_EXECUTION_DATE='2024-06-20T13:54:21.717901+00:00' AIRFLOW_CTX_TRY_NUMBER='1' AIRFLOW_CTX_DAG_RUN_ID='manual__2024-06-20T13:54:21.717901+00:00'
[2024-06-20T13:54:35.449+0000] {taskinstance.py:430} INFO - ::endgroup::
[2024-06-20T13:54:35.455+0000] {subprocess.py:63} INFO - Tmp dir root location: /tmp
[2024-06-20T13:54:35.457+0000] {subprocess.py:75} INFO - Running command: ['/usr/bin/bash', '-c', 'cp -r /opt/***/data/output/landing_file.csv pgdb:/var/lib/postgresql/data/landing_file.csv']
[2024-06-20T13:54:35.475+0000] {subprocess.py:86} INFO - Output:
[2024-06-20T13:54:35.521+0000] {subprocess.py:93} INFO - cp: cannot create regular file 'pgdb:/var/lib/postgresql/data/landing_file.csv': No such file or directory
[2024-06-20T13:54:35.524+0000] {subprocess.py:97} INFO - Command exited with return code 1
[2024-06-20T13:54:35.527+0000] {taskinstance.py:441} INFO - ::group::Post task execution logs
[2024-06-20T13:54:35.545+0000] {taskinstance.py:2905} ERROR - Task failed with exception
Traceback (most recent call last):
  File "/home/airflow/.local/lib/python3.12/site-packages/airflow/models/taskinstance.py", line 465, in _execute_task
    result = _execute_callable(context=context, **execute_callable_kwargs)
             ^^^^^^^^^^^^^^^^^^^^^^^^^^^^^^^^^^^^^^^^^^^^^^^^^^^^^^^^^^^^^
  File "/home/airflow/.local/lib/python3.12/site-packages/airflow/models/taskinstance.py", line 432, in _execute_callable
    return execute_callable(context=context, **execute_callable_kwargs)
           ^^^^^^^^^^^^^^^^^^^^^^^^^^^^^^^^^^^^^^^^^^^^^^^^^^^^^^^^^^^^
  File "/home/airflow/.local/lib/python3.12/site-packages/airflow/models/baseoperator.py", line 401, in wrapper
    return func(self, *args, **kwargs)
           ^^^^^^^^^^^^^^^^^^^^^^^^^^^
  File "/home/airflow/.local/lib/python3.12/site-packages/airflow/operators/bash.py", line 243, in execute
    raise AirflowException(
airflow.exceptions.AirflowException: Bash command failed. The command returned a non-zero exit code 1.
[2024-06-20T13:54:35.551+0000] {taskinstance.py:1206} INFO - Marking task as UP_FOR_RETRY. dag_id=testing_dag, task_id=copy_to_db, run_id=manual__2024-06-20T13:54:21.717901+00:00, execution_date=20240620T135421, start_date=20240620T135435, end_date=20240620T135435
[2024-06-20T13:54:35.582+0000] {standard_task_runner.py:110} ERROR - Failed to execute job 129 for task copy_to_db (Bash command failed. The command returned a non-zero exit code 1.; 1428)
[2024-06-20T13:54:35.615+0000] {local_task_job_runner.py:240} INFO - Task exited with return code 1
[2024-06-20T13:54:35.646+0000] {taskinstance.py:3503} INFO - 0 downstream tasks scheduled from follow-on schedule check
[2024-06-20T13:54:35.649+0000] {local_task_job_runner.py:222} INFO - ::endgroup::
