[2024-06-20T12:15:53.535+0000] {local_task_job_runner.py:120} INFO - ::group::Pre task execution logs
[2024-06-20T12:15:53.577+0000] {taskinstance.py:2076} INFO - Dependencies all met for dep_context=non-requeueable deps ti=<TaskInstance: testing_dag.load_data manual__2024-06-20T12:10:33.418514+00:00 [queued]>
[2024-06-20T12:15:53.588+0000] {taskinstance.py:2076} INFO - Dependencies all met for dep_context=requeueable deps ti=<TaskInstance: testing_dag.load_data manual__2024-06-20T12:10:33.418514+00:00 [queued]>
[2024-06-20T12:15:53.590+0000] {taskinstance.py:2306} INFO - Starting attempt 2 of 2
[2024-06-20T12:15:53.609+0000] {taskinstance.py:2330} INFO - Executing <Task(SQLExecuteQueryOperator): load_data> on 2024-06-20 12:10:33.418514+00:00
[2024-06-20T12:15:53.619+0000] {warnings.py:112} WARNING - /home/***/.local/lib/python3.12/site-packages/***/task/task_runner/standard_task_runner.py:61: DeprecationWarning: This process (pid=134) is multi-threaded, use of fork() may lead to deadlocks in the child.
  pid = os.fork()

[2024-06-20T12:15:53.622+0000] {standard_task_runner.py:90} INFO - Running: ['***', 'tasks', 'run', 'testing_dag', 'load_data', 'manual__2024-06-20T12:10:33.418514+00:00', '--job-id', '108', '--raw', '--subdir', 'DAGS_FOLDER/main_dag.py', '--cfg-path', '/tmp/tmpl1cu5wep']
[2024-06-20T12:15:53.623+0000] {standard_task_runner.py:63} INFO - Started process 136 to run task
[2024-06-20T12:15:53.624+0000] {standard_task_runner.py:91} INFO - Job 108: Subtask load_data
[2024-06-20T12:15:53.664+0000] {task_command.py:426} INFO - Running <TaskInstance: testing_dag.load_data manual__2024-06-20T12:10:33.418514+00:00 [running]> on host 3c14a6b849f8
[2024-06-20T12:15:53.742+0000] {taskinstance.py:2648} INFO - Exporting env vars: AIRFLOW_CTX_DAG_EMAIL='***@example.com' AIRFLOW_CTX_DAG_OWNER='***' AIRFLOW_CTX_DAG_ID='testing_dag' AIRFLOW_CTX_TASK_ID='load_data' AIRFLOW_CTX_EXECUTION_DATE='2024-06-20T12:10:33.418514+00:00' AIRFLOW_CTX_TRY_NUMBER='2' AIRFLOW_CTX_DAG_RUN_ID='manual__2024-06-20T12:10:33.418514+00:00'
[2024-06-20T12:15:53.743+0000] {taskinstance.py:430} INFO - ::endgroup::
[2024-06-20T12:15:53.744+0000] {sql.py:276} INFO - Executing: BEGIN TRANSACTION;
COPY raw_external_fund FROM '/opt/***/data/output/landing_file.csv' WITH (FORMAT CSV);
COMMIT;
[2024-06-20T12:15:53.753+0000] {base.py:84} INFO - Using connection ID 'postgres_***' for task execution.
[2024-06-20T12:15:53.763+0000] {base.py:84} INFO - Using connection ID 'postgres_***' for task execution.
[2024-06-20T12:15:53.797+0000] {sql.py:487} INFO - Running statement: BEGIN TRANSACTION;
COPY raw_external_fund FROM '/opt/***/data/output/landing_file.csv' WITH (FORMAT CSV);
COMMIT;, parameters: None
[2024-06-20T12:15:53.807+0000] {taskinstance.py:441} INFO - ::group::Post task execution logs
[2024-06-20T12:15:53.808+0000] {taskinstance.py:2905} ERROR - Task failed with exception
Traceback (most recent call last):
  File "/home/airflow/.local/lib/python3.12/site-packages/airflow/models/taskinstance.py", line 465, in _execute_task
    result = _execute_callable(context=context, **execute_callable_kwargs)
             ^^^^^^^^^^^^^^^^^^^^^^^^^^^^^^^^^^^^^^^^^^^^^^^^^^^^^^^^^^^^^
  File "/home/airflow/.local/lib/python3.12/site-packages/airflow/models/taskinstance.py", line 432, in _execute_callable
    return execute_callable(context=context, **execute_callable_kwargs)
           ^^^^^^^^^^^^^^^^^^^^^^^^^^^^^^^^^^^^^^^^^^^^^^^^^^^^^^^^^^^^
  File "/home/airflow/.local/lib/python3.12/site-packages/airflow/models/baseoperator.py", line 401, in wrapper
    return func(self, *args, **kwargs)
           ^^^^^^^^^^^^^^^^^^^^^^^^^^^
  File "/home/airflow/.local/lib/python3.12/site-packages/airflow/providers/common/sql/operators/sql.py", line 282, in execute
    output = hook.run(
             ^^^^^^^^^
  File "/home/airflow/.local/lib/python3.12/site-packages/airflow/providers/common/sql/hooks/sql.py", line 435, in run
    self._run_command(cur, sql_statement, parameters)
  File "/home/airflow/.local/lib/python3.12/site-packages/airflow/providers/common/sql/hooks/sql.py", line 492, in _run_command
    cur.execute(sql_statement)
psycopg2.errors.UndefinedFile: could not open file "/opt/***/data/output/landing_file.csv" for reading: No such file or directory
HINT:  COPY FROM instructs the PostgreSQL server process to read a file. You may want a client-side facility such as psql's \copy.

[2024-06-20T12:15:53.823+0000] {taskinstance.py:1206} INFO - Marking task as FAILED. dag_id=testing_dag, task_id=load_data, run_id=manual__2024-06-20T12:10:33.418514+00:00, execution_date=20240620T121033, start_date=20240620T121553, end_date=20240620T121553
[2024-06-20T12:15:53.838+0000] {standard_task_runner.py:110} ERROR - Failed to execute job 108 for task load_data (could not open file "/opt/***/data/output/landing_file.csv" for reading: No such file or directory
HINT:  COPY FROM instructs the PostgreSQL server process to read a file. You may want a client-side facility such as psql's \copy.
; 136)
[2024-06-20T12:15:53.878+0000] {local_task_job_runner.py:240} INFO - Task exited with return code 1
[2024-06-20T12:15:53.893+0000] {taskinstance.py:3503} INFO - 0 downstream tasks scheduled from follow-on schedule check
[2024-06-20T12:15:53.896+0000] {local_task_job_runner.py:222} INFO - ::endgroup::
