[2024-06-20T14:22:03.126+0000] {local_task_job_runner.py:120} INFO - ::group::Pre task execution logs
[2024-06-20T14:22:03.166+0000] {taskinstance.py:2076} INFO - Dependencies all met for dep_context=non-requeueable deps ti=<TaskInstance: testing_dag.copy_to_db manual__2024-06-20T14:16:40.105565+00:00 [queued]>
[2024-06-20T14:22:03.178+0000] {taskinstance.py:2076} INFO - Dependencies all met for dep_context=requeueable deps ti=<TaskInstance: testing_dag.copy_to_db manual__2024-06-20T14:16:40.105565+00:00 [queued]>
[2024-06-20T14:22:03.179+0000] {taskinstance.py:2306} INFO - Starting attempt 2 of 2
[2024-06-20T14:22:03.195+0000] {taskinstance.py:2330} INFO - Executing <Task(BashOperator): copy_to_db> on 2024-06-20 14:16:40.105565+00:00
[2024-06-20T14:22:03.209+0000] {warnings.py:112} WARNING - /home/***/.local/lib/python3.12/site-packages/***/task/task_runner/standard_task_runner.py:61: DeprecationWarning: This process (pid=1808) is multi-threaded, use of fork() may lead to deadlocks in the child.
  pid = os.fork()

[2024-06-20T14:22:03.210+0000] {standard_task_runner.py:63} INFO - Started process 1810 to run task
[2024-06-20T14:22:03.210+0000] {standard_task_runner.py:90} INFO - Running: ['***', 'tasks', 'run', 'testing_dag', 'copy_to_db', 'manual__2024-06-20T14:16:40.105565+00:00', '--job-id', '139', '--raw', '--subdir', 'DAGS_FOLDER/main_dag.py', '--cfg-path', '/tmp/tmprp6f5mkm']
[2024-06-20T14:22:03.211+0000] {standard_task_runner.py:91} INFO - Job 139: Subtask copy_to_db
[2024-06-20T14:22:03.264+0000] {task_command.py:426} INFO - Running <TaskInstance: testing_dag.copy_to_db manual__2024-06-20T14:16:40.105565+00:00 [running]> on host 3c14a6b849f8
[2024-06-20T14:22:03.363+0000] {taskinstance.py:2648} INFO - Exporting env vars: AIRFLOW_CTX_DAG_EMAIL='***@example.com' AIRFLOW_CTX_DAG_OWNER='***' AIRFLOW_CTX_DAG_ID='testing_dag' AIRFLOW_CTX_TASK_ID='copy_to_db' AIRFLOW_CTX_EXECUTION_DATE='2024-06-20T14:16:40.105565+00:00' AIRFLOW_CTX_TRY_NUMBER='2' AIRFLOW_CTX_DAG_RUN_ID='manual__2024-06-20T14:16:40.105565+00:00'
[2024-06-20T14:22:03.366+0000] {taskinstance.py:430} INFO - ::endgroup::
[2024-06-20T14:22:03.371+0000] {subprocess.py:63} INFO - Tmp dir root location: /tmp
[2024-06-20T14:22:03.382+0000] {subprocess.py:75} INFO - Running command: ['/usr/bin/bash', '-c', 'docker cp /opt/***/data/output/landing_file.csv pgdb:/var/lib/postgresql/data/landing_file.csv']
[2024-06-20T14:22:03.409+0000] {subprocess.py:86} INFO - Output:
[2024-06-20T14:22:03.523+0000] {subprocess.py:93} INFO - Cannot connect to the Docker daemon at unix:///var/run/docker.sock. Is the docker daemon running?
[2024-06-20T14:22:03.525+0000] {subprocess.py:97} INFO - Command exited with return code 1
[2024-06-20T14:22:03.527+0000] {taskinstance.py:441} INFO - ::group::Post task execution logs
[2024-06-20T14:22:03.545+0000] {taskinstance.py:2905} ERROR - Task failed with exception
Traceback (most recent call last):
  File "/home/airflow/.local/lib/python3.12/site-packages/airflow/models/taskinstance.py", line 465, in _execute_task
    result = _execute_callable(context=context, **execute_callable_kwargs)
             ^^^^^^^^^^^^^^^^^^^^^^^^^^^^^^^^^^^^^^^^^^^^^^^^^^^^^^^^^^^^^
  File "/home/airflow/.local/lib/python3.12/site-packages/airflow/models/taskinstance.py", line 432, in _execute_callable
    return execute_callable(context=context, **execute_callable_kwargs)
           ^^^^^^^^^^^^^^^^^^^^^^^^^^^^^^^^^^^^^^^^^^^^^^^^^^^^^^^^^^^^
  File "/home/airflow/.local/lib/python3.12/site-packages/airflow/models/baseoperator.py", line 401, in wrapper
    return func(self, *args, **kwargs)
           ^^^^^^^^^^^^^^^^^^^^^^^^^^^
  File "/home/airflow/.local/lib/python3.12/site-packages/airflow/operators/bash.py", line 243, in execute
    raise AirflowException(
airflow.exceptions.AirflowException: Bash command failed. The command returned a non-zero exit code 1.
[2024-06-20T14:22:03.555+0000] {taskinstance.py:1206} INFO - Marking task as FAILED. dag_id=testing_dag, task_id=copy_to_db, run_id=manual__2024-06-20T14:16:40.105565+00:00, execution_date=20240620T141640, start_date=20240620T142203, end_date=20240620T142203
[2024-06-20T14:22:03.595+0000] {standard_task_runner.py:110} ERROR - Failed to execute job 139 for task copy_to_db (Bash command failed. The command returned a non-zero exit code 1.; 1810)
[2024-06-20T14:22:03.626+0000] {local_task_job_runner.py:240} INFO - Task exited with return code 1
[2024-06-20T14:22:03.655+0000] {taskinstance.py:3503} INFO - 0 downstream tasks scheduled from follow-on schedule check
[2024-06-20T14:22:03.658+0000] {local_task_job_runner.py:222} INFO - ::endgroup::
