[2024-06-20T14:16:55.163+0000] {local_task_job_runner.py:120} INFO - ::group::Pre task execution logs
[2024-06-20T14:16:55.230+0000] {taskinstance.py:2076} INFO - Dependencies all met for dep_context=non-requeueable deps ti=<TaskInstance: testing_dag.copy_to_db manual__2024-06-20T14:16:40.105565+00:00 [queued]>
[2024-06-20T14:16:55.241+0000] {taskinstance.py:2076} INFO - Dependencies all met for dep_context=requeueable deps ti=<TaskInstance: testing_dag.copy_to_db manual__2024-06-20T14:16:40.105565+00:00 [queued]>
[2024-06-20T14:16:55.243+0000] {taskinstance.py:2306} INFO - Starting attempt 1 of 2
[2024-06-20T14:16:55.260+0000] {taskinstance.py:2330} INFO - Executing <Task(BashOperator): copy_to_db> on 2024-06-20 14:16:40.105565+00:00
[2024-06-20T14:16:55.271+0000] {warnings.py:112} WARNING - /home/***/.local/lib/python3.12/site-packages/***/task/task_runner/standard_task_runner.py:61: DeprecationWarning: This process (pid=1734) is multi-threaded, use of fork() may lead to deadlocks in the child.
  pid = os.fork()

[2024-06-20T14:16:55.274+0000] {standard_task_runner.py:63} INFO - Started process 1736 to run task
[2024-06-20T14:16:55.273+0000] {standard_task_runner.py:90} INFO - Running: ['***', 'tasks', 'run', 'testing_dag', 'copy_to_db', 'manual__2024-06-20T14:16:40.105565+00:00', '--job-id', '138', '--raw', '--subdir', 'DAGS_FOLDER/main_dag.py', '--cfg-path', '/tmp/tmps4h69f25']
[2024-06-20T14:16:55.276+0000] {standard_task_runner.py:91} INFO - Job 138: Subtask copy_to_db
[2024-06-20T14:16:55.349+0000] {task_command.py:426} INFO - Running <TaskInstance: testing_dag.copy_to_db manual__2024-06-20T14:16:40.105565+00:00 [running]> on host 3c14a6b849f8
[2024-06-20T14:16:55.490+0000] {taskinstance.py:2648} INFO - Exporting env vars: AIRFLOW_CTX_DAG_EMAIL='***@example.com' AIRFLOW_CTX_DAG_OWNER='***' AIRFLOW_CTX_DAG_ID='testing_dag' AIRFLOW_CTX_TASK_ID='copy_to_db' AIRFLOW_CTX_EXECUTION_DATE='2024-06-20T14:16:40.105565+00:00' AIRFLOW_CTX_TRY_NUMBER='1' AIRFLOW_CTX_DAG_RUN_ID='manual__2024-06-20T14:16:40.105565+00:00'
[2024-06-20T14:16:55.494+0000] {taskinstance.py:430} INFO - ::endgroup::
[2024-06-20T14:16:55.501+0000] {subprocess.py:63} INFO - Tmp dir root location: /tmp
[2024-06-20T14:16:55.515+0000] {subprocess.py:75} INFO - Running command: ['/usr/bin/bash', '-c', 'docker cp /opt/***/data/output/landing_file.csv pgdb:/var/lib/postgresql/data/landing_file.csv']
[2024-06-20T14:16:55.559+0000] {subprocess.py:86} INFO - Output:
[2024-06-20T14:16:55.666+0000] {subprocess.py:93} INFO - Cannot connect to the Docker daemon at unix:///var/run/docker.sock. Is the docker daemon running?
[2024-06-20T14:16:55.669+0000] {subprocess.py:97} INFO - Command exited with return code 1
[2024-06-20T14:16:55.670+0000] {taskinstance.py:441} INFO - ::group::Post task execution logs
[2024-06-20T14:16:55.689+0000] {taskinstance.py:2905} ERROR - Task failed with exception
Traceback (most recent call last):
  File "/home/airflow/.local/lib/python3.12/site-packages/airflow/models/taskinstance.py", line 465, in _execute_task
    result = _execute_callable(context=context, **execute_callable_kwargs)
             ^^^^^^^^^^^^^^^^^^^^^^^^^^^^^^^^^^^^^^^^^^^^^^^^^^^^^^^^^^^^^
  File "/home/airflow/.local/lib/python3.12/site-packages/airflow/models/taskinstance.py", line 432, in _execute_callable
    return execute_callable(context=context, **execute_callable_kwargs)
           ^^^^^^^^^^^^^^^^^^^^^^^^^^^^^^^^^^^^^^^^^^^^^^^^^^^^^^^^^^^^
  File "/home/airflow/.local/lib/python3.12/site-packages/airflow/models/baseoperator.py", line 401, in wrapper
    return func(self, *args, **kwargs)
           ^^^^^^^^^^^^^^^^^^^^^^^^^^^
  File "/home/airflow/.local/lib/python3.12/site-packages/airflow/operators/bash.py", line 243, in execute
    raise AirflowException(
airflow.exceptions.AirflowException: Bash command failed. The command returned a non-zero exit code 1.
[2024-06-20T14:16:55.698+0000] {taskinstance.py:1206} INFO - Marking task as UP_FOR_RETRY. dag_id=testing_dag, task_id=copy_to_db, run_id=manual__2024-06-20T14:16:40.105565+00:00, execution_date=20240620T141640, start_date=20240620T141655, end_date=20240620T141655
[2024-06-20T14:16:55.721+0000] {standard_task_runner.py:110} ERROR - Failed to execute job 138 for task copy_to_db (Bash command failed. The command returned a non-zero exit code 1.; 1736)
[2024-06-20T14:16:55.772+0000] {local_task_job_runner.py:240} INFO - Task exited with return code 1
[2024-06-20T14:16:55.787+0000] {taskinstance.py:3503} INFO - 0 downstream tasks scheduled from follow-on schedule check
[2024-06-20T14:16:55.789+0000] {local_task_job_runner.py:222} INFO - ::endgroup::
